[2023-07-28T15:37:17.139+0200] {taskinstance.py:1103} INFO - Dependencies all met for dep_context=non-requeueable deps ti=<TaskInstance: monthly_statistics.extract_and_load_data manual__2023-07-28T13:37:15.116102+00:00 [queued]>
[2023-07-28T15:37:17.143+0200] {taskinstance.py:1103} INFO - Dependencies all met for dep_context=requeueable deps ti=<TaskInstance: monthly_statistics.extract_and_load_data manual__2023-07-28T13:37:15.116102+00:00 [queued]>
[2023-07-28T15:37:17.144+0200] {taskinstance.py:1308} INFO - Starting attempt 1 of 1
[2023-07-28T15:37:17.150+0200] {taskinstance.py:1327} INFO - Executing <Task(PythonOperator): extract_and_load_data> on 2023-07-28 13:37:15.116102+00:00
[2023-07-28T15:37:17.152+0200] {standard_task_runner.py:57} INFO - Started process 24223 to run task
[2023-07-28T15:37:17.155+0200] {standard_task_runner.py:84} INFO - Running: ['airflow', 'tasks', 'run', 'monthly_statistics', 'extract_and_load_data', 'manual__2023-07-28T13:37:15.116102+00:00', '--job-id', '10', '--raw', '--subdir', 'DAGS_FOLDER/monthly_statistics.py', '--cfg-path', '/var/folders/s3/52f8ptfd1wg8m_7fvtgb9g0w0000gn/T/tmp3fvd09f8']
[2023-07-28T15:37:17.155+0200] {standard_task_runner.py:85} INFO - Job 10: Subtask extract_and_load_data
[2023-07-28T15:37:17.199+0200] {task_command.py:410} INFO - Running <TaskInstance: monthly_statistics.extract_and_load_data manual__2023-07-28T13:37:15.116102+00:00 [running]> on host gabriel-3.home
[2023-07-28T15:37:17.257+0200] {taskinstance.py:1545} INFO - Exporting env vars: AIRFLOW_CTX_DAG_OWNER='airflow' AIRFLOW_CTX_DAG_ID='monthly_statistics' AIRFLOW_CTX_TASK_ID='extract_and_load_data' AIRFLOW_CTX_EXECUTION_DATE='2023-07-28T13:37:15.116102+00:00' AIRFLOW_CTX_TRY_NUMBER='1' AIRFLOW_CTX_DAG_RUN_ID='manual__2023-07-28T13:37:15.116102+00:00'
[2023-07-28T15:37:17.315+0200] {taskinstance.py:1824} ERROR - Task failed with exception
Traceback (most recent call last):
  File "/opt/homebrew/lib/python3.10/site-packages/sqlalchemy/engine/base.py", line 3371, in _wrap_pool_connect
    return fn()
  File "/opt/homebrew/lib/python3.10/site-packages/sqlalchemy/pool/base.py", line 327, in connect
    return _ConnectionFairy._checkout(self)
  File "/opt/homebrew/lib/python3.10/site-packages/sqlalchemy/pool/base.py", line 894, in _checkout
    fairy = _ConnectionRecord.checkout(pool)
  File "/opt/homebrew/lib/python3.10/site-packages/sqlalchemy/pool/base.py", line 493, in checkout
    rec = pool._do_get()
  File "/opt/homebrew/lib/python3.10/site-packages/sqlalchemy/pool/impl.py", line 145, in _do_get
    with util.safe_reraise():
  File "/opt/homebrew/lib/python3.10/site-packages/sqlalchemy/util/langhelpers.py", line 70, in __exit__
    compat.raise_(
  File "/opt/homebrew/lib/python3.10/site-packages/sqlalchemy/util/compat.py", line 211, in raise_
    raise exception
  File "/opt/homebrew/lib/python3.10/site-packages/sqlalchemy/pool/impl.py", line 143, in _do_get
    return self._create_connection()
  File "/opt/homebrew/lib/python3.10/site-packages/sqlalchemy/pool/base.py", line 273, in _create_connection
    return _ConnectionRecord(self)
  File "/opt/homebrew/lib/python3.10/site-packages/sqlalchemy/pool/base.py", line 388, in __init__
    self.__connect()
  File "/opt/homebrew/lib/python3.10/site-packages/sqlalchemy/pool/base.py", line 690, in __connect
    with util.safe_reraise():
  File "/opt/homebrew/lib/python3.10/site-packages/sqlalchemy/util/langhelpers.py", line 70, in __exit__
    compat.raise_(
  File "/opt/homebrew/lib/python3.10/site-packages/sqlalchemy/util/compat.py", line 211, in raise_
    raise exception
  File "/opt/homebrew/lib/python3.10/site-packages/sqlalchemy/pool/base.py", line 686, in __connect
    self.dbapi_connection = connection = pool._invoke_creator(self)
  File "/opt/homebrew/lib/python3.10/site-packages/sqlalchemy/engine/create.py", line 574, in connect
    return dialect.connect(*cargs, **cparams)
  File "/opt/homebrew/lib/python3.10/site-packages/sqlalchemy/engine/default.py", line 598, in connect
    return self.dbapi.connect(*cargs, **cparams)
  File "/opt/homebrew/lib/python3.10/site-packages/psycopg2/__init__.py", line 122, in connect
    conn = _connect(dsn, connection_factory=connection_factory, **kwasync)
psycopg2.OperationalError: could not translate host name "postgres_airflow" to address: nodename nor servname provided, or not known


The above exception was the direct cause of the following exception:

Traceback (most recent call last):
  File "/opt/homebrew/lib/python3.10/site-packages/airflow/operators/python.py", line 181, in execute
    return_value = self.execute_callable()
  File "/opt/homebrew/lib/python3.10/site-packages/airflow/operators/python.py", line 198, in execute_callable
    return self.python_callable(*self.op_args, **self.op_kwargs)
  File "/Users/gabriel-macbook/airflow/dags/monthly_statistics.py", line 33, in extract_and_load_data
    df.to_sql('bookings_table', engine, if_exists='replace', index=False)
  File "/opt/homebrew/lib/python3.10/site-packages/pandas/core/generic.py", line 2878, in to_sql
    return sql.to_sql(
  File "/opt/homebrew/lib/python3.10/site-packages/pandas/io/sql.py", line 768, in to_sql
    with pandasSQL_builder(con, schema=schema, need_transaction=True) as pandas_sql:
  File "/opt/homebrew/lib/python3.10/site-packages/pandas/io/sql.py", line 832, in pandasSQL_builder
    return SQLDatabase(con, schema, need_transaction)
  File "/opt/homebrew/lib/python3.10/site-packages/pandas/io/sql.py", line 1539, in __init__
    con = self.exit_stack.enter_context(con.connect())
  File "/opt/homebrew/lib/python3.10/site-packages/sqlalchemy/engine/base.py", line 3325, in connect
    return self._connection_cls(self, close_with_result=close_with_result)
  File "/opt/homebrew/lib/python3.10/site-packages/sqlalchemy/engine/base.py", line 96, in __init__
    else engine.raw_connection()
  File "/opt/homebrew/lib/python3.10/site-packages/sqlalchemy/engine/base.py", line 3404, in raw_connection
    return self._wrap_pool_connect(self.pool.connect, _connection)
  File "/opt/homebrew/lib/python3.10/site-packages/sqlalchemy/engine/base.py", line 3374, in _wrap_pool_connect
    Connection._handle_dbapi_exception_noconnection(
  File "/opt/homebrew/lib/python3.10/site-packages/sqlalchemy/engine/base.py", line 2208, in _handle_dbapi_exception_noconnection
    util.raise_(
  File "/opt/homebrew/lib/python3.10/site-packages/sqlalchemy/util/compat.py", line 211, in raise_
    raise exception
  File "/opt/homebrew/lib/python3.10/site-packages/sqlalchemy/engine/base.py", line 3371, in _wrap_pool_connect
    return fn()
  File "/opt/homebrew/lib/python3.10/site-packages/sqlalchemy/pool/base.py", line 327, in connect
    return _ConnectionFairy._checkout(self)
  File "/opt/homebrew/lib/python3.10/site-packages/sqlalchemy/pool/base.py", line 894, in _checkout
    fairy = _ConnectionRecord.checkout(pool)
  File "/opt/homebrew/lib/python3.10/site-packages/sqlalchemy/pool/base.py", line 493, in checkout
    rec = pool._do_get()
  File "/opt/homebrew/lib/python3.10/site-packages/sqlalchemy/pool/impl.py", line 145, in _do_get
    with util.safe_reraise():
  File "/opt/homebrew/lib/python3.10/site-packages/sqlalchemy/util/langhelpers.py", line 70, in __exit__
    compat.raise_(
  File "/opt/homebrew/lib/python3.10/site-packages/sqlalchemy/util/compat.py", line 211, in raise_
    raise exception
  File "/opt/homebrew/lib/python3.10/site-packages/sqlalchemy/pool/impl.py", line 143, in _do_get
    return self._create_connection()
  File "/opt/homebrew/lib/python3.10/site-packages/sqlalchemy/pool/base.py", line 273, in _create_connection
    return _ConnectionRecord(self)
  File "/opt/homebrew/lib/python3.10/site-packages/sqlalchemy/pool/base.py", line 388, in __init__
    self.__connect()
  File "/opt/homebrew/lib/python3.10/site-packages/sqlalchemy/pool/base.py", line 690, in __connect
    with util.safe_reraise():
  File "/opt/homebrew/lib/python3.10/site-packages/sqlalchemy/util/langhelpers.py", line 70, in __exit__
    compat.raise_(
  File "/opt/homebrew/lib/python3.10/site-packages/sqlalchemy/util/compat.py", line 211, in raise_
    raise exception
  File "/opt/homebrew/lib/python3.10/site-packages/sqlalchemy/pool/base.py", line 686, in __connect
    self.dbapi_connection = connection = pool._invoke_creator(self)
  File "/opt/homebrew/lib/python3.10/site-packages/sqlalchemy/engine/create.py", line 574, in connect
    return dialect.connect(*cargs, **cparams)
  File "/opt/homebrew/lib/python3.10/site-packages/sqlalchemy/engine/default.py", line 598, in connect
    return self.dbapi.connect(*cargs, **cparams)
  File "/opt/homebrew/lib/python3.10/site-packages/psycopg2/__init__.py", line 122, in connect
    conn = _connect(dsn, connection_factory=connection_factory, **kwasync)
sqlalchemy.exc.OperationalError: (psycopg2.OperationalError) could not translate host name "postgres_airflow" to address: nodename nor servname provided, or not known

(Background on this error at: https://sqlalche.me/e/14/e3q8)
[2023-07-28T15:37:17.333+0200] {taskinstance.py:1345} INFO - Marking task as FAILED. dag_id=monthly_statistics, task_id=extract_and_load_data, execution_date=20230728T133715, start_date=20230728T133717, end_date=20230728T133717
[2023-07-28T15:37:17.340+0200] {standard_task_runner.py:104} ERROR - Failed to execute job 10 for task extract_and_load_data ((psycopg2.OperationalError) could not translate host name "postgres_airflow" to address: nodename nor servname provided, or not known

(Background on this error at: https://sqlalche.me/e/14/e3q8); 24223)
[2023-07-28T15:37:17.375+0200] {local_task_job_runner.py:225} INFO - Task exited with return code 1
[2023-07-28T15:37:17.394+0200] {taskinstance.py:2653} INFO - 0 downstream tasks scheduled from follow-on schedule check
